<!--URDF generated by ONSHAPE BY PTC INC, 1.217-->
<robot name="pkg_4_dof_robotic_arm_10_snapshot_2">
    <link name="01__base">
        <inertial>
            <mass value="0.0223896" />
            <origin xyz="1.70649e-05 -0.0280827 0.0929643" rpy="0 -0 0" />
            <inertia ixx="0.000490466" ixy="8.37363e-08" ixz="-1.50147e-08" iyy="0.0004038" iyz="4.7447e-05" izz="0.000587776" />
        </inertial>
        <visual>
            <origin xyz="0 0 0" rpy="0 -0 0" />
            <geometry>
                <mesh filename="package://pkg_4_dof_robotic_arm_10_snapshot_2/meshes/_01__Base.stl" scale="1 1 1" />
            </geometry>
            <material name="0.200000_0.200000_0.200000_0.000000_0.000000">
                <color rgba="0.2 0.2 0.2 1" />
            </material>
        </visual>
    </link>
    <link name="02__link_c33_conne">
        <inertial>
            <mass value="0.00417834" />
            <origin xyz="6.10694e-18 -0.0178967 0.197023" rpy="0 -0 0" />
            <inertia ixx="0.000153998" ixy="0" ixz="0" iyy="0.000163233" iyz="-5.70424e-07" izz="1.04173e-05" />
        </inertial>
        <visual>
            <origin xyz="0 0 0" rpy="0 -0 0" />
            <geometry>
                <mesh filename="package://pkg_4_dof_robotic_arm_10_snapshot_2/meshes/_02__Link_C33_Conne.stl" scale="1 1 1" />
            </geometry>
            <material name="0.796078_0.823529_0.937255_0.000000_0.000000">
                <color rgba="0.796078 0.823529 0.937255 1" />
            </material>
        </visual>
    </link>
    <link name="0_3_link_c22">
        <inertial>
            <mass value="0.0141295" />
            <origin xyz="-5.81054e-13 5.16481e-13 0.0896566" rpy="0 -0 0" />
            <inertia ixx="0.000273047" ixy="1.85702e-15" ixz="0" iyy="0.000299584" iyz="-1.32132e-15" izz="0.000107308" />
        </inertial>
        <visual>
            <origin xyz="0 0 -0.12" rpy="0 -0 0" />
            <geometry>
                <mesh filename="package://pkg_4_dof_robotic_arm_10_snapshot_2/meshes/_0_3_Link_C22.stl" scale="1 1 1" />
            </geometry>
            <material name="0.266667_0.266667_0.266667_0.000000_0.000000">
                <color rgba="0.266667 0.266667 0.266667 1" />
            </material>
        </visual>
    </link>
    <link name="0_4_link_c33">
        <inertial>
            <mass value="0.010704" />
            <origin xyz="1.33201e-07 0.131394 0.200966" rpy="0 6.62806e-07 0" />
            <inertia ixx="0.000496698" ixy="4.13631e-12" ixz="-2.846e-10" iyy="0.000463271" iyz="6.24061e-06" izz="6.73118e-05" />
        </inertial>
        <visual>
            <origin xyz="1.65701e-07 0.09 0.25" rpy="0 6.62806e-07 0" />
            <geometry>
                <mesh filename="package://pkg_4_dof_robotic_arm_10_snapshot_2/meshes/_0_4_Link_C33.stl" scale="1 1 1" />
            </geometry>
            <material name="0.796078_0.823529_0.937255_0.000000_0.000000">
                <color rgba="0.796078 0.823529 0.937255 1" />
            </material>
        </visual>
    </link>
    <link name="0_5_tool_holder">
        <inertial>
            <mass value="0.00737733" />
            <origin xyz="0.0385082 0.08 0.0987897" rpy="0 -0 0" />
            <inertia ixx="4.95139e-05" ixy="0" ixz="-9.05418e-06" iyy="8.32835e-05" iyz="-2.98545e-15" izz="5.9108e-05" />
        </inertial>
        <visual>
            <origin xyz="0.0319158 0.08 0.0544511" rpy="0 -0 0" />
            <geometry>
                <mesh filename="package://pkg_4_dof_robotic_arm_10_snapshot_2/meshes/_0_5_Tool_Holder.stl" scale="1 1 1" />
            </geometry>
            <material name="0.796078_0.823529_0.937255_0.000000_0.000000">
                <color rgba="0.796078 0.823529 0.937255 1" />
            </material>
        </visual>
    </link>
    <link name="0_6_revolver">
        <inertial>
            <mass value="0.00513812" />
            <origin xyz="0.0979277 -1.05792e-18 -6.31076e-18" rpy="0 -0 0" />
            <inertia ixx="2.90971e-05" ixy="0" ixz="0" iyy="3.82602e-05" iyz="0" izz="4.82803e-05" />
        </inertial>
        <visual>
            <origin xyz="0.22 0 0" rpy="0 -0 0" />
            <geometry>
                <mesh filename="package://pkg_4_dof_robotic_arm_10_snapshot_2/meshes/_0_6_Revolver.stl" scale="1 1 1" />
            </geometry>
            <material name="1.000000_0.949020_0.909804_0.000000_0.000000">
                <color rgba="1 0.94902 0.909804 1" />
            </material>
        </visual>
    </link>
    <link name="0_7_combiner">
        <inertial>
            <mass value="0.00187461" />
            <origin xyz="-0.00201824 -0.118219 -3.38884e-19" rpy="0 -0 0" />
            <inertia ixx="9.84693e-06" ixy="-3.66164e-07" ixz="0" iyy="2.94428e-06" iyz="0" izz="1.00202e-05" />
        </inertial>
        <visual>
            <origin xyz="0 -0.105 0" rpy="0 -0 0" />
            <geometry>
                <mesh filename="package://pkg_4_dof_robotic_arm_10_snapshot_2/meshes/_0_7_Combiner.stl" scale="1 1 1" />
            </geometry>
            <material name="0.796078_0.823529_0.937255_0.000000_0.000000">
                <color rgba="0.796078 0.823529 0.937255 1" />
            </material>
        </visual>
    </link>
    <link name="0_8_cutter">
        <inertial>
            <mass value="0.00136397" />
            <origin xyz="0.0082759 -0.05 -1.10973e-06" rpy="0 -0 0" />
            <inertia ixx="2.43545e-06" ixy="0" ixz="-1.07355e-10" iyy="8.93381e-06" iyz="0" izz="8.4347e-06" />
        </inertial>
        <visual>
            <origin xyz="0 -0.05 0" rpy="0 -0 0" />
            <geometry>
                <mesh filename="package://pkg_4_dof_robotic_arm_10_snapshot_2/meshes/_0_8_Cutter.stl" scale="1 1 1" />
            </geometry>
            <material name="0.796078_0.823529_0.937255_0.000000_0.000000">
                <color rgba="0.796078 0.823529 0.937255 1" />
            </material>
        </visual>
    </link>
    <link name="root" />
    <joint name="fastened_1" type="fixed">
        <origin xyz="0 -2.22045e-16 0.29" rpy="-2.08167e-16 1.80411e-16 1.5708" />
        <axis xyz="0 0 -1" />
        <parent link="01__base" />
        <child link="0_3_link_c22" />
    </joint>
    <joint name="fastened_2" type="fixed">
        <origin xyz="0.22 0.1 -2.22045e-16" rpy="2.77556e-17 -5.55112e-17 -2.08167e-17" />
        <axis xyz="0 1 0" />
        <parent link="0_6_revolver" />
        <child link="0_7_combiner" />
    </joint>
    <joint name="fastened_3" type="fixed">
        <origin xyz="-1.11022e-16 1.55431e-15 1.42109e-14" rpy="1.60982e-15 6.62806e-07 -1.07552e-16" />
        <axis xyz="0 1 0" />
        <parent link="0_4_link_c33" />
        <child link="02__link_c33_conne" />
    </joint>
    <joint name="fixed_node_to_root_joint" type="fixed">
        <origin xyz="-1.26658 -0.882823 -0.296737" rpy="0.277545 -0.134555 -0.00551775" />
        <axis xyz="0 0 1" />
        <parent link="root" />
        <child link="01__base" />
    </joint>
    <joint name="revolute_1" type="continuous">
        <origin xyz="1.11022e-16 -0.09 0.216" rpy="-4.16334e-17 5.55112e-17 -8.08891e-33" />
        <axis xyz="0 1 0" />
        <parent link="0_3_link_c22" />
        <child link="0_4_link_c33" />
    </joint>
    <joint name="revolute_2" type="continuous">
        <origin xyz="3.31403e-07 6.66134e-16 0.5" rpy="-4.16334e-17 6.62806e-07 6.93888e-18" />
        <axis xyz="0 1 0" />
        <parent link="0_4_link_c33" />
        <child link="0_5_tool_holder" />
    </joint>
    <joint name="revolute_3" type="continuous">
        <origin xyz="0.231916 0.08 0.129451" rpy="1.38778e-17 -2.77556e-17 -6.93889e-18" />
        <axis xyz="-1 0 0" />
        <parent link="0_5_tool_holder" />
        <child link="0_6_revolver" />
    </joint>
    <joint name="revolute_4" type="continuous">
        <origin xyz="0.22 0.05 0" rpy="0 1.5708 -6.93889e-18" />
        <axis xyz="0 1 0" />
        <parent link="0_6_revolver" />
        <child link="0_8_cutter" />
    </joint>
</robot>
